Workbook
Name AccessoFonte: '01_Liste'!$Q$2:$Q$5
Name Affidabilita: '01_Liste'!$N$2:$N$6
Name AzioniLog: '01_Liste'!$R$2:$R$6
Name BarrieraOOpportunita: '01_Liste'!$Z$2:$Z$3
Name Booleane: '01_Liste'!$T$2:$T$4
Name CategorieBarriere: '01_Liste'!$H$2:$H$9
Name EsitoVerifica: '01_Liste'!$AA$2:$AA$4
Name FaseSviluppo: '01_Liste'!$D$2:$D$8
Name FrequenzeAgg: '01_Liste'!$P$2:$P$7
Name Geografie: '01_Liste'!$K$2:$K$8
Name IntensitaImpatto: '01_Liste'!$W$2:$W$4
Name KPI_Tecnici: '01_Liste'!$J$2:$J$9
Name LivelloAnalisi: '01_Liste'!$C$2:$C$4
Name MacroCategorie: '01_Liste'!$A$2:$A$6
Name MetricheCosto: '01_Liste'!$E$2:$E$9
Name Orizzonti: '01_Liste'!$X$2:$X$4
Name SettoriEconomici: '01_Liste'!$F$2:$F$9
Name SourceIDs: '02_Fonti'!$A$4:$A$14
Name StatiPolicy: '01_Liste'!$Y$2:$Y$5
Name StatoMonitoraggio: '01_Liste'!$B$2:$B$6
Name TassonomiaUE: '01_Liste'!$O$2:$O$5
Name TechIDs: '03_Tecnologie'!$A$4:$A$14
Name TipiAttore: '01_Liste'!$I$2:$I$11
Name TipiFonte: '01_Liste'!$M$2:$M$9
Name TipiPolicy: '01_Liste'!$G$2:$G$9
Name Trend: '01_Liste'!$V$2:$V$5
Name TRL: '01_Liste'!$S$2:$S$10
Name Valute: '01_Liste'!$U$2:$U$5

Sheet 00_Executive
A1: ERMES | Executive finale con ranking e semafori
A2: Vista per decisori: ranking sintetico delle tecnologie osservate, semafori per attrattivita, policy fit e copertura dati. Il punteggio executive combina strategia/mercato (25%), maturita tecnologica (15%), prontezza industriale (15%), competitivita economica (20%), sostenibilita/policy fit (20%) e copertura informativa (5%).
B4: Score medio portafoglio | F4: Tecnologie in verde | J4: Tecnologie in giallo | N4: Tecnologie in rosso
B5: =IFERROR(AVERAGE('99_Exec_Helper'!$T$5:$T$35),0) -> 68.291667 | F5: =COUNTIF('99_Exec_Helper'!$V$5:$V$35,"VERDE") -> 4 | J5: =COUNTIF('99_Exec_Helper'!$V$5:$V$35,"GIALLO") -> 5 | N5: =COUNTIF('99_Exec_Helper'!$V$5:$V$35,"ROSSO") -> 3
B7: Indice medio 0-100 | F7: Accelerare / selezionare | J7: Selettive / da pilotare | N7: Presidiare / phase-out
B9: Tecnologie globali / multi-mercato | F9: Copertura dati media | J9: Fossili in rosso | N9: Leader portafoglio
B10: =COUNTIFS('99_Exec_Helper'!$D$5:$D$35,"Entrambi / globale",'99_Exec_Helper'!$V$5:$V$35,"VERDE")+COUNTIFS('99_Exec_Helper'!$D$5:$D$35,"Globale",'99_Exec_Helper'!$V$5:$V$35,"VERDE")+COUNTIFS('99_Exec_Helper'!$D$5:$D$35,"Misto",'99_Exec_Helper'!$V$5:$V$35,"VERDE") -> 0 | F10: =IFERROR(AVERAGE('99_Exec_Helper'!$J$5:$J$35),0) -> 0.84027778 | J10: =COUNTIFS('99_Exec_Helper'!$C$5:$C$35,"Fossili",'99_Exec_Helper'!$V$5:$V$35,"ROSSO") -> 2 | N10: =INDEX('99_Exec_Helper'!$B$5:$B$35,MATCH(1,'99_Exec_Helper'!$U$5:$U$35,0))&CHAR(10)&TEXT(INDEX('99_Exec_Helper'!$T$5:$T$35,MATCH(1,'99_Exec_Helper'!$U$5:$U$35,0)),"0.0") -> Fotovoltaico 90
B12: Mercato ampio + semaforo verde | F12: Copertura aree osservatorio | J12: Tecnologie fossili penalizzate | N12: Prima nel ranking
A14: Sintesi decisionale: watchlist e ranking finale
A15: Leggi cosi: VERDE = accelerare, GIALLO = selezionare / pilotare, ROSSO = presidiare o mantenere per motivi di continuita / sicurezza.
A16: Top 3 da accelerare | J16: Ultimi 3 / da presidiare
A17: Rank | B17: Tecnologia | C17: Score | D17: Semaforo | E17: Posizionamento | J17: Rank | K17: Tecnologia | L17: Score | M17: Semaforo | N17: Posizionamento
A18: 1 | B18: =IFERROR(INDEX('99_Exec_Helper'!$B$5:$B$35,MATCH($A18,'99_Exec_Helper'!$U$5:$U$35,0)),"") -> Fotovoltaico | C18: =IFERROR(INDEX('99_Exec_Helper'!$T$5:$T$35,MATCH($A18,'99_Exec_Helper'!$U$5:$U$35,0)),"") -> 90.1 | D18: =IFERROR(INDEX('99_Exec_Helper'!$V$5:$V$35,MATCH($A18,'99_Exec_Helper'!$U$5:$U$35,0)),"") -> VERDE | E18: =IFERROR(INDEX('99_Exec_Helper'!$Z$5:$Z$35,MATCH($A18,'99_Exec_Helper'!$U$5:$U$35,0)),"") -> Leader | J18: =MAX('99_Exec_Helper'!$U$5:$U$35)-3+ROW()-17 -> 10 | K18: =IFERROR(INDEX('99_Exec_Helper'!$B$5:$B$35,MATCH($J18,'99_Exec_Helper'!$U$5:$U$35,0)),"") -> Carbone | L18: =IFERROR(INDEX('99_Exec_Helper'!$T$5:$T$35,MATCH($J18,'99_Exec_Helper'!$U$5:$U$35,0)),"") -> 52.8 | M18: =IFERROR(INDEX('99_Exec_Helper'!$V$5:$V$35,MATCH($J18,'99_Exec_Helper'!$U$5:$U$35,0)),"") -> ROSSO | N18: =IFERROR(INDEX('99_Exec_Helper'!$Z$5:$Z$35,MATCH($J18,'99_Exec_Helper'!$U$5:$U$35,0)),"") -> Presidio
A19: 2 | B19: =IFERROR(INDEX('99_Exec_Helper'!$B$5:$B$35,MATCH($A19,'99_Exec_Helper'!$U$5:$U$35,0)),"") -> Eolico | C19: =IFERROR(INDEX('99_Exec_Helper'!$T$5:$T$35,MATCH($A19,'99_Exec_Helper'!$U$5:$U$35,0)),"") -> 88.1 | D19: =IFERROR(INDEX('99_Exec_Helper'!$V$5:$V$35,MATCH($A19,'99_Exec_Helper'!$U$5:$U$35,0)),"") -> VERDE | E19: =IFERROR(INDEX('99_Exec_Helper'!$Z$5:$Z$35,MATCH($A19,'99_Exec_Helper'!$U$5:$U$35,0)),"") -> Leader | J19: =MAX('99_Exec_Helper'!$U$5:$U$35)-3+ROW()-17 -> 11 | K19: =IFERROR(INDEX('99_Exec_Helper'!$B$5:$B$35,MATCH($J19,'99_Exec_Helper'!$U$5:$U$35,0)),"") -> Olio | L19: =IFERROR(INDEX('99_Exec_Helper'!$T$5:$T$35,MATCH($J19,'99_Exec_Helper'!$U$5:$U$35,0)),"") -> 46.1 | M19: =IFERROR(INDEX('99_Exec_Helper'!$V$5:$V$35,MATCH($J19,'99_Exec_Helper'!$U$5:$U$35,0)),"") -> ROSSO | N19: =IFERROR(INDEX('99_Exec_Helper'!$Z$5:$Z$35,MATCH($J19,'99_Exec_Helper'!$U$5:$U$35,0)),"") -> Presidio
A20: 3 | B20: =IFERROR(INDEX('99_Exec_Helper'!$B$5:$B$35,MATCH($A20,'99_Exec_Helper'!$U$5:$U$35,0)),"") -> Idroelettrico | C20: =IFERROR(INDEX('99_Exec_Helper'!$T$5:$T$35,MATCH($A20,'99_Exec_Helper'!$U$5:$U$35,0)),"") -> 83.2 | D20: =IFERROR(INDEX('99_Exec_Helper'!$V$5:$V$35,MATCH($A20,'99_Exec_Helper'!$U$5:$U$35,0)),"") -> VERDE | E20: =IFERROR(INDEX('99_Exec_Helper'!$Z$5:$Z$35,MATCH($A20,'99_Exec_Helper'!$U$5:$U$35,0)),"") -> Core | J20: =MAX('99_Exec_Helper'!$U$5:$U$35)-3+ROW()-17 -> 12 | K20: =IFERROR(INDEX('99_Exec_Helper'!$B$5:$B$35,MATCH($J20,'99_Exec_Helper'!$U$5:$U$35,0)),"") -> 0 | L20: =IFERROR(INDEX('99_Exec_Helper'!$T$5:$T$35,MATCH($J20,'99_Exec_Helper'!$U$5:$U$35,0)),"") -> 35.5 | M20: =IFERROR(INDEX('99_Exec_Helper'!$V$5:$V$35,MATCH($J20,'99_Exec_Helper'!$U$5:$U$35,0)),"") -> ROSSO | N20: =IFERROR(INDEX('99_Exec_Helper'!$Z$5:$Z$35,MATCH($J20,'99_Exec_Helper'!$U$5:$U$35,0)),"") -> Presidio
A23: Ranking integrale del portafoglio tecnologico
A24: Il ranking e dinamico e si aggiorna dalle anagrafiche e dai fogli analitici tramite 99_Exec_Helper.
A26: Rank | B26: Tecnologia | C26: Macro-categoria | D26: Mercato di riferimento | E26: Score executive | F26: Posizionamento | G26: Semaforo exec | H26: Semaforo policy | I26: Semaforo dati | J26: TRL | K26: Costo / competitivita | L26: Raccomandazione
A27: 1 | B27: =IFERROR(INDEX('99_Exec_Helper'!$B$5:$B$35,MATCH($A27,'99_Exec_Helper'!$U$5:$U$35,0)),"") -> Fotovoltaico | C27: =IFERROR(INDEX('99_Exec_Helper'!$C$5:$C$35,MATCH($A27,'99_Exec_Helper'!$U$5:$U$35,0)),"") -> Rinnovabili | D27: =IFERROR(INDEX('99_Exec_Helper'!$D$5:$D$35,MATCH($A27,'99_Exec_Helper'!$U$5:$U$35,0)),"") -> 0 | E27: =IFERROR(INDEX('99_Exec_Helper'!$T$5:$T$35,MATCH($A27,'99_Exec_Helper'!$U$5:$U$35,0)),"") -> 90.1 | F27: =IFERROR(INDEX('99_Exec_Helper'!$Z$5:$Z$35,MATCH($A27,'99_Exec_Helper'!$U$5:$U$35,0)),"") -> Leader | G27: =IFERROR(INDEX('99_Exec_Helper'!$V$5:$V$35,MATCH($A27,'99_Exec_Helper'!$U$5:$U$35,0)),"") -> VERDE | H27: =IFERROR(INDEX('99_Exec_Helper'!$X$5:$X$35,MATCH($A27,'99_Exec_Helper'!$U$5:$U$35,0)),"") -> VERDE | I27: =IFERROR(INDEX('99_Exec_Helper'!$W$5:$W$35,MATCH($A27,'99_Exec_Helper'!$U$5:$U$35,0)),"") -> VERDE | J27: =IFERROR(INDEX('99_Exec_Helper'!$F$5:$F$35,MATCH($A27,'99_Exec_Helper'!$U$5:$U$35,0)),"") -> 9 | K27: =IFERROR(INDEX('99_Exec_Helper'!$H$5:$H$35,MATCH($A27,'99_Exec_Helper'!$U$5:$U$35,0)),"") -> Molto competitivo | L27: =IFERROR(INDEX('99_Exec_Helper'!$Y$5:$Y$35,MATCH($A27,'99_Exec_Helper'!$U$5:$U$35,0)),"") -> ACCELERARE
A28: 2 | B28: =IFERROR(INDEX('99_Exec_Helper'!$B$5:$B$35,MATCH($A28,'99_Exec_Helper'!$U$5:$U$35,0)),"") -> Eolico | C28: =IFERROR(INDEX('99_Exec_Helper'!$C$5:$C$35,MATCH($A28,'99_Exec_Helper'!$U$5:$U$35,0)),"") -> Rinnovabili | D28: =IFERROR(INDEX('99_Exec_Helper'!$D$5:$D$35,MATCH($A28,'99_Exec_Helper'!$U$5:$U$35,0)),"") -> 0 | E28: =IFERROR(INDEX('99_Exec_Helper'!$T$5:$T$35,MATCH($A28,'99_Exec_Helper'!$U$5:$U$35,0)),"") -> 88.1 | F28: =IFERROR(INDEX('99_Exec_Helper'!$Z$5:$Z$35,MATCH($A28,'99_Exec_Helper'!$U$5:$U$35,0)),"") -> Leader | G28: =IFERROR(INDEX('99_Exec_Helper'!$V$5:$V$35,MATCH($A28,'99_Exec_Helper'!$U$5:$U$35,0)),"") -> VERDE | H28: =IFERROR(INDEX('99_Exec_Helper'!$X$5:$X$35,MATCH($A28,'99_Exec_Helper'!$U$5:$U$35,0)),"") -> VERDE | I28: =IFERROR(INDEX('99_Exec_Helper'!$W$5:$W$35,MATCH($A28,'99_Exec_Helper'!$U$5:$U$35,0)),"") -> VERDE | J28: =IFERROR(INDEX('99_Exec_Helper'!$F$5:$F$35,MATCH($A28,'99_Exec_Helper'!$U$5:$U$35,0)),"") -> 9 | K28: =IFERROR(INDEX('99_Exec_Helper'!$H$5:$H$35,MATCH($A28,'99_Exec_Helper'!$U$5:$U$35,0)),"") -> Competitivo | L28: =IFERROR(INDEX('99_Exec_Helper'!$Y$5:$Y$35,MATCH($A28,'99_Exec_Helper'!$U$5:$U$35,0)),"") -> ACCELERARE
A29: 3 | B29: =IFERROR(INDEX('99_Exec_Helper'!$B$5:$B$35,MATCH($A29,'99_Exec_Helper'!$U$5:$U$35,0)),"") -> Idroelettrico | C29: =IFERROR(INDEX('99_Exec_Helper'!$C$5:$C$35,MATCH($A29,'99_Exec_Helper'!$U$5:$U$35,0)),"") -> Rinnovabili | D29: =IFERROR(INDEX('99_Exec_Helper'!$D$5:$D$35,MATCH($A29,'99_Exec_Helper'!$U$5:$U$35,0)),"") -> 0 | E29: =IFERROR(INDEX('99_Exec_Helper'!$T$5:$T$35,MATCH($A29,'99_Exec_Helper'!$U$5:$U$35,0)),"") -> 83.2 | F29: =IFERROR(INDEX('99_Exec_Helper'!$Z$5:$Z$35,MATCH($A29,'99_Exec_Helper'!$U$5:$U$35,0)),"") -> Core | G29: =IFERROR(INDEX('99_Exec_Helper'!$V$5:$V$35,MATCH($A29,'99_Exec_Helper'!$U$5:$U$35,0)),"") -> VERDE | H29: =IFERROR(INDEX('99_Exec_Helper'!$X$5:$X$35,MATCH($A29,'99_Exec_Helper'!$U$5:$U$35,0)),"") -> VERDE | I29: =IFERROR(INDEX('99_Exec_Helper'!$W$5:$W$35,MATCH($A29,'99_Exec_Helper'!$U$5:$U$35,0)),"") -> VERDE | J29: =IFERROR(INDEX('99_Exec_Helper'!$F$5:$F$35,MATCH($A29,'99_Exec_Helper'!$U$5:$U$35,0)),"") -> 9 | K29: =IFERROR(INDEX('99_Exec_Helper'!$H$5:$H$35,MATCH($A29,'99_Exec_Helper'!$U$5:$U$35,0)),"") -> 40-120 EUR/MWh | L29: =IFERROR(INDEX('99_Exec_Helper'!$Y$5:$Y$35,MATCH($A29,'99_Exec_Helper'!$U$5:$U$35,0)),"") -> ACCELERARE
A30: 4 | B30: =IFERROR(INDEX('99_Exec_Helper'!$B$5:$B$35,MATCH($A30,'99_Exec_Helper'!$U$5:$U$35,0)),"") -> Geotermico | C30: =IFERROR(INDEX('99_Exec_Helper'!$C$5:$C$35,MATCH($A30,'99_Exec_Helper'!$U$5:$U$35,0)),"") -> Rinnovabili | D30: =IFERROR(INDEX('99_Exec_Helper'!$D$5:$D$35,MATCH($A30,'99_Exec_Helper'!$U$5:$U$35,0)),"") -> 0 | E30: =IFERROR(INDEX('99_Exec_Helper'!$T$5:$T$35,MATCH($A30,'99_Exec_Helper'!$U$5:$U$35,0)),"") -> 80.5 | F30: =IFERROR(INDEX('99_Exec_Helper'!$Z$5:$Z$35,MATCH($A30,'99_Exec_Helper'!$U$5:$U$35,0)),"") -> Core | G30: =IFERROR(INDEX('99_Exec_Helper'!$V$5:$V$35,MATCH($A30,'99_Exec_Helper'!$U$5:$U$35,0)),"") -> VERDE | H30: =IFERROR(INDEX('99_Exec_Helper'!$X$5:$X$35,MATCH($A30,'99_Exec_Helper'!$U$5:$U$35,0)),"") -> VERDE | I30: =IFERROR(INDEX('99_Exec_Helper'!$W$5:$W$35,MATCH($A30,'99_Exec_Helper'!$U$5:$U$35,0)),"") -> VERDE | J30: =IFERROR(INDEX('99_Exec_Helper'!$F$5:$F$35,MATCH($A30,'99_Exec_Helper'!$U$5:$U$35,0)),"") -> 8 | K30: =IFERROR(INDEX('99_Exec_Helper'!$H$5:$H$35,MATCH($A30,'99_Exec_Helper'!$U$5:$U$35,0)),"") -> 45-120 EUR/MWh | L30: =IFERROR(INDEX('99_Exec_Helper'!$Y$5:$Y$35,MATCH($A30,'99_Exec_Helper'!$U$5:$U$35,0)),"") -> ACCELERARE
A31: 5 | B31: =IFERROR(INDEX('99_Exec_Helper'!$B$5:$B$35,MATCH($A31,'99_Exec_Helper'!$U$5:$U$35,0)),"") -> Idrogeno verde | C31: =IFERROR(INDEX('99_Exec_Helper'!$C$5:$C$35,MATCH($A31,'99_Exec_Helper'!$U$5:$U$35,0)),"") -> Vettori innovativi | D31: =IFERROR(INDEX('99_Exec_Helper'!$D$5:$D$35,MATCH($A31,'99_Exec_Helper'!$U$5:$U$35,0)),"") -> 0 | E31: =IFERROR(INDEX('99_Exec_Helper'!$T$5:$T$35,MATCH($A31,'99_Exec_Helper'!$U$5:$U$35,0)),"") -> 77.3 | F31: =IFERROR(INDEX('99_Exec_Helper'!$Z$5:$Z$35,MATCH($A31,'99_Exec_Helper'!$U$5:$U$35,0)),"") -> Core | G31: =IFERROR(INDEX('99_Exec_Helper'!$V$5:$V$35,MATCH($A31,'99_Exec_Helper'!$U$5:$U$35,0)),"") -> GIALLO | H31: =IFERROR(INDEX('99_Exec_Helper'!$X$5:$X$35,MATCH($A31,'99_Exec_Helper'!$U$5:$U$35,0)),"") -> GIALLO | I31: =IFERROR(INDEX('99_Exec_Helper'!$W$5:$W$35,MATCH($A31,'99_Exec_Helper'!$U$5:$U$35,0)),"") -> VERDE | J31: =IFERROR(INDEX('99_Exec_Helper'!$F$5:$F$35,MATCH($A31,'99_Exec_Helper'!$U$5:$U$35,0)),"") -> 7-8 | K31: =IFERROR(INDEX('99_Exec_Helper'!$H$5:$H$35,MATCH($A31,'99_Exec_Helper'!$U$5:$U$35,0)),"") -> Fuel cost-driven | L31: =IFERROR(INDEX('99_Exec_Helper'!$Y$5:$Y$35,MATCH($A31,'99_Exec_Helper'!$U$5:$U$35,0)),"") -> SELEZIONARE / PILOTARE
A32: 6 | B32: =IFERROR(INDEX('99_Exec_Helper'!$B$5:$B$35,MATCH($A32,'99_Exec_Helper'!$U$5:$U$35,0)),"") -> Solare Termico | C32: =IFERROR(INDEX('99_Exec_Helper'!$C$5:$C$35,MATCH($A32,'99_Exec_Helper'!$U$5:$U$35,0)),"") -> Rinnovabili | D32: =IFERROR(INDEX('99_Exec_Helper'!$D$5:$D$35,MATCH($A32,'99_Exec_Helper'!$U$5:$U$35,0)),"") -> 0 | E32: =IFERROR(INDEX('99_Exec_Helper'!$T$5:$T$35,MATCH($A32,'99_Exec_Helper'!$U$5:$U$35,0)),"") -> 71.2 | F32: =IFERROR(INDEX('99_Exec_Helper'!$Z$5:$Z$35,MATCH($A32,'99_Exec_Helper'!$U$5:$U$35,0)),"") -> Selettiva | G32: =IFERROR(INDEX('99_Exec_Helper'!$V$5:$V$35,MATCH($A32,'99_Exec_Helper'!$U$5:$U$35,0)),"") -> GIALLO | H32: =IFERROR(INDEX('99_Exec_Helper'!$X$5:$X$35,MATCH($A32,'99_Exec_Helper'!$U$5:$U$35,0)),"") -> VERDE | I32: =IFERROR(INDEX('99_Exec_Helper'!$W$5:$W$35,MATCH($A32,'99_Exec_Helper'!$U$5:$U$35,0)),"") -> VERDE | J32: =IFERROR(INDEX('99_Exec_Helper'!$F$5:$F$35,MATCH($A32,'99_Exec_Helper'!$U$5:$U$35,0)),"") -> 8 | K32: =IFERROR(INDEX('99_Exec_Helper'!$H$5:$H$35,MATCH($A32,'99_Exec_Helper'!$U$5:$U$35,0)),"") -> 110-220 EUR/MWh | L32: =IFERROR(INDEX('99_Exec_Helper'!$Y$5:$Y$35,MATCH($A32,'99_Exec_Helper'!$U$5:$U$35,0)),"") -> SELEZIONARE / PILOTARE
A33: 7 | B33: =IFERROR(INDEX('99_Exec_Helper'!$B$5:$B$35,MATCH($A33,'99_Exec_Helper'!$U$5:$U$35,0)),"") -> Gas Naturale | C33: =IFERROR(INDEX('99_Exec_Helper'!$C$5:$C$35,MATCH($A33,'99_Exec_Helper'!$U$5:$U$35,0)),"") -> Fossili | D33: =IFERROR(INDEX('99_Exec_Helper'!$D$5:$D$35,MATCH($A33,'99_Exec_Helper'!$U$5:$U$35,0)),"") -> 0 | E33: =IFERROR(INDEX('99_Exec_Helper'!$T$5:$T$35,MATCH($A33,'99_Exec_Helper'!$U$5:$U$35,0)),"") -> 65.3 | F33: =IFERROR(INDEX('99_Exec_Helper'!$Z$5:$Z$35,MATCH($A33,'99_Exec_Helper'!$U$5:$U$35,0)),"") -> Selettiva | G33: =IFERROR(INDEX('99_Exec_Helper'!$V$5:$V$35,MATCH($A33,'99_Exec_Helper'!$U$5:$U$35,0)),"") -> GIALLO | H33: =IFERROR(INDEX('99_Exec_Helper'!$X$5:$X$35,MATCH($A33,'99_Exec_Helper'!$U$5:$U$35,0)),"") -> GIALLO | I33: =IFERROR(INDEX('99_Exec_Helper'!$W$5:$W$35,MATCH($A33,'99_Exec_Helper'!$U$5:$U$35,0)),"") -> VERDE | J33: =IFERROR(INDEX('99_Exec_Helper'!$F$5:$F$35,MATCH($A33,'99_Exec_Helper'!$U$5:$U$35,0)),"") -> 9 | K33: =IFERROR(INDEX('99_Exec_Helper'!$H$5:$H$35,MATCH($A33,'99_Exec_Helper'!$U$5:$U$35,0)),"") -> 70-120 EUR/MWh | L33: =IFERROR(INDEX('99_Exec_Helper'!$Y$5:$Y$35,MATCH($A33,'99_Exec_Helper'!$U$5:$U$35,0)),"") -> SELEZIONARE / PILOTARE
A34: 8 | B34: =IFERROR(INDEX('99_Exec_Helper'!$B$5:$B$35,MATCH($A34,'99_Exec_Helper'!$U$5:$U$35,0)),"") -> Biomasse | C34: =IFERROR(INDEX('99_Exec_Helper'!$C$5:$C$35,MATCH($A34,'99_Exec_Helper'!$U$5:$U$35,0)),"") -> Rinnovabili | D34: =IFERROR(INDEX('99_Exec_Helper'!$D$5:$D$35,MATCH($A34,'99_Exec_Helper'!$U$5:$U$35,0)),"") -> 0 | E34: =IFERROR(INDEX('99_Exec_Helper'!$T$5:$T$35,MATCH($A34,'99_Exec_Helper'!$U$5:$U$35,0)),"") -> 64.7 | F34: =IFERROR(INDEX('99_Exec_Helper'!$Z$5:$Z$35,MATCH($A34,'99_Exec_Helper'!$U$5:$U$35,0)),"") -> Selettiva | G34: =IFERROR(INDEX('99_Exec_Helper'!$V$5:$V$35,MATCH($A34,'99_Exec_Helper'!$U$5:$U$35,0)),"") -> GIALLO | H34: =IFERROR(INDEX('99_Exec_Helper'!$X$5:$X$35,MATCH($A34,'99_Exec_Helper'!$U$5:$U$35,0)),"") -> GIALLO | I34: =IFERROR(INDEX('99_Exec_Helper'!$W$5:$W$35,MATCH($A34,'99_Exec_Helper'!$U$5:$U$35,0)),"") -> VERDE | J34: =IFERROR(INDEX('99_Exec_Helper'!$F$5:$F$35,MATCH($A34,'99_Exec_Helper'!$U$5:$U$35,0)),"") -> 8 | K34: =IFERROR(INDEX('99_Exec_Helper'!$H$5:$H$35,MATCH($A34,'99_Exec_Helper'!$U$5:$U$35,0)),"") -> 90-180 EUR/MWh | L34: =IFERROR(INDEX('99_Exec_Helper'!$Y$5:$Y$35,MATCH($A34,'99_Exec_Helper'!$U$5:$U$35,0)),"") -> SELEZIONARE / PILOTARE
A35: 9 | B35: =IFERROR(INDEX('99_Exec_Helper'!$B$5:$B$35,MATCH($A35,'99_Exec_Helper'!$U$5:$U$35,0)),"") -> Nucleare da fissione | C35: =IFERROR(INDEX('99_Exec_Helper'!$C$5:$C$35,MATCH($A35,'99_Exec_Helper'!$U$5:$U$35,0)),"") -> Basse emissioni / transitorie | D35: =IFERROR(INDEX('99_Exec_Helper'!$D$5:$D$35,MATCH($A35,'99_Exec_Helper'!$U$5:$U$35,0)),"") -> 0 | E35: =IFERROR(INDEX('99_Exec_Helper'!$T$5:$T$35,MATCH($A35,'99_Exec_Helper'!$U$5:$U$35,0)),"") -> 64.7 | F35: =IFERROR(INDEX('99_Exec_Helper'!$Z$5:$Z$35,MATCH($A35,'99_Exec_Helper'!$U$5:$U$35,0)),"") -> Selettiva | G35: =IFERROR(INDEX('99_Exec_Helper'!$V$5:$V$35,MATCH($A35,'99_Exec_Helper'!$U$5:$U$35,0)),"") -> GIALLO | H35: =IFERROR(INDEX('99_Exec_Helper'!$X$5:$X$35,MATCH($A35,'99_Exec_Helper'!$U$5:$U$35,0)),"") -> GIALLO | I35: =IFERROR(INDEX('99_Exec_Helper'!$W$5:$W$35,MATCH($A35,'99_Exec_Helper'!$U$5:$U$35,0)),"") -> VERDE | J35: =IFERROR(INDEX('99_Exec_Helper'!$F$5:$F$35,MATCH($A35,'99_Exec_Helper'!$U$5:$U$35,0)),"") -> 8 | K35: =IFERROR(INDEX('99_Exec_Helper'!$H$5:$H$35,MATCH($A35,'99_Exec_Helper'!$U$5:$U$35,0)),"") -> 90-180 EUR/MWh | L35: =IFERROR(INDEX('99_Exec_Helper'!$Y$5:$Y$35,MATCH($A35,'99_Exec_Helper'!$U$5:$U$35,0)),"") -> SELEZIONARE / PILOTARE
A36: 10 | B36: =IFERROR(INDEX('99_Exec_Helper'!$B$5:$B$35,MATCH($A36,'99_Exec_Helper'!$U$5:$U$35,0)),"") -> Carbone | C36: =IFERROR(INDEX('99_Exec_Helper'!$C$5:$C$35,MATCH($A36,'99_Exec_Helper'!$U$5:$U$35,0)),"") -> Fossili | D36: =IFERROR(INDEX('99_Exec_Helper'!$D$5:$D$35,MATCH($A36,'99_Exec_Helper'!$U$5:$U$35,0)),"") -> 0 | E36: =IFERROR(INDEX('99_Exec_Helper'!$T$5:$T$35,MATCH($A36,'99_Exec_Helper'!$U$5:$U$35,0)),"") -> 52.8 | F36: =IFERROR(INDEX('99_Exec_Helper'!$Z$5:$Z$35,MATCH($A36,'99_Exec_Helper'!$U$5:$U$35,0)),"") -> Presidio | G36: =IFERROR(INDEX('99_Exec_Helper'!$V$5:$V$35,MATCH($A36,'99_Exec_Helper'!$U$5:$U$35,0)),"") -> ROSSO | H36: =IFERROR(INDEX('99_Exec_Helper'!$X$5:$X$35,MATCH($A36,'99_Exec_Helper'!$U$5:$U$35,0)),"") -> ROSSO | I36: =IFERROR(INDEX('99_Exec_Helper'!$W$5:$W$35,MATCH($A36,'99_Exec_Helper'!$U$5:$U$35,0)),"") -> VERDE | J36: =IFERROR(INDEX('99_Exec_Helper'!$F$5:$F$35,MATCH($A36,'99_Exec_Helper'!$U$5:$U$35,0)),"") -> 9 | K36: =IFERROR(INDEX('99_Exec_Helper'!$H$5:$H$35,MATCH($A36,'99_Exec_Helper'!$U$5:$U$35,0)),"") -> 90-160 EUR/MWh | L36: =IFERROR(INDEX('99_Exec_Helper'!$Y$5:$Y$35,MATCH($A36,'99_Exec_Helper'!$U$5:$U$35,0)),"") -> PRESIDIARE / PHASE-OUT
A37: 11 | B37: =IFERROR(INDEX('99_Exec_Helper'!$B$5:$B$35,MATCH($A37,'99_Exec_Helper'!$U$5:$U$35,0)),"") -> Olio | C37: =IFERROR(INDEX('99_Exec_Helper'!$C$5:$C$35,MATCH($A37,'99_Exec_Helper'!$U$5:$U$35,0)),"") -> Fossili | D37: =IFERROR(INDEX('99_Exec_Helper'!$D$5:$D$35,MATCH($A37,'99_Exec_Helper'!$U$5:$U$35,0)),"") -> 0 | E37: =IFERROR(INDEX('99_Exec_Helper'!$T$5:$T$35,MATCH($A37,'99_Exec_Helper'!$U$5:$U$35,0)),"") -> 46.1 | F37: =IFERROR(INDEX('99_Exec_Helper'!$Z$5:$Z$35,MATCH($A37,'99_Exec_Helper'!$U$5:$U$35,0)),"") -> Presidio | G37: =IFERROR(INDEX('99_Exec_Helper'!$V$5:$V$35,MATCH($A37,'99_Exec_Helper'!$U$5:$U$35,0)),"") -> ROSSO | H37: =IFERROR(INDEX('99_Exec_Helper'!$X$5:$X$35,MATCH($A37,'99_Exec_Helper'!$U$5:$U$35,0)),"") -> ROSSO | I37: =IFERROR(INDEX('99_Exec_Helper'!$W$5:$W$35,MATCH($A37,'99_Exec_Helper'!$U$5:$U$35,0)),"") -> VERDE | J37: =IFERROR(INDEX('99_Exec_Helper'!$F$5:$F$35,MATCH($A37,'99_Exec_Helper'!$U$5:$U$35,0)),"") -> 9 | K37: =IFERROR(INDEX('99_Exec_Helper'!$H$5:$H$35,MATCH($A37,'99_Exec_Helper'!$U$5:$U$35,0)),"") -> 130-220 EUR/MWh | L37: =IFERROR(INDEX('99_Exec_Helper'!$Y$5:$Y$35,MATCH($A37,'99_Exec_Helper'!$U$5:$U$35,0)),"") -> PRESIDIARE / PHASE-OUT

Sheet 00_Dashboard
A1: ERMES | Dashboard manageriale e KPI sintetici
A2: Cruscotto executive per seguire il popolamento dell'Osservatorio. Le metriche leggono in automatico le anagrafiche e i fogli analitici; si aggiornano man mano che compili il database.
B4: Fonti censite | F4: Tecnologie monitorate | J4: Perimetro mercati | N4: Record analitici
B5: =COUNTA('02_Fonti'!$A$4:$A$1000) -> 121 | F5: =COUNTA('03_Tecnologie'!$A$4:$A$1000) -> 12 | J5: =COUNTA('04_Componenti'!$A$4:$A$1000) -> 69 | N5: =SUM('00_Scorecard'!$T$4:$T$1000) -> 694
B7: Repertorio fonti | F7: Tecnologie attive in anagrafica | J7: Classificazione mercati di riferimento | N7: Somma di tutte le aree
B9: Copertura media aree | F9: TRL/TLR medio | J9: Mercati perimetro | N9: Copertura avanzata
B10: =IFERROR(AVERAGEIF('00_Scorecard'!$R$4:$R$1000,">0"),0) -> 0.91666667 | F10: =IFERROR(AVERAGEIF('00_Scorecard'!$S$4:$S$1000,">0"),0) -> 8.2121212 | J10: =COUNTIF('03_Tecnologie'!$H$4:$H$1000,"<>") -> 0 | N10: =COUNTIF('00_Scorecard'!$U$4:$U$1000,"Copertura avanzata") -> 11
B12: Quota media aree coperte | F12: Solo tecnologie con dati TRL | J12: Tecnologie senza perimetro mercato | N12: Tecnologie oltre il 70%
J13: =COUNTIFS('03_Tecnologie'!$A$4:$A$1000,"<>",'03_Tecnologie'!$H$4:$H$1000,"") -> 12
A14: Sintesi per tecnologia (vista rapida)
A15: La tabella sotto riprende la scorecard manageriale. Se una tecnologia ha copertura bassa o presidio informativo limitato, il database va rafforzato prima.
A17: Tecnologia | B17: Stato monitoraggio | C17: Copertura | D17: Stato manageriale | E17: Priorita di popolamento
A18: =IF('00_Scorecard'!B4="","",'00_Scorecard'!B4) -> Carbone | B18: =IF($A18="","",'00_Scorecard'!D4) -> Monitoraggio attivo | C18: =IF($A18="","",'00_Scorecard'!R4) -> 0.91666667 | D18: =IF($A18="","",'00_Scorecard'!U4) -> Copertura avanzata | E18: =IF($A18="","",'00_Scorecard'!V4) -> Presidio adeguato
A19: =IF('00_Scorecard'!B5="","",'00_Scorecard'!B5) -> Olio | B19: =IF($A19="","",'00_Scorecard'!D5) -> Archiviata | C19: =IF($A19="","",'00_Scorecard'!R5) -> 0.91666667 | D19: =IF($A19="","",'00_Scorecard'!U5) -> Copertura avanzata | E19: =IF($A19="","",'00_Scorecard'!V5) -> Presidio adeguato
A20: =IF('00_Scorecard'!B6="","",'00_Scorecard'!B6) -> Gas Naturale | B20: =IF($A20="","",'00_Scorecard'!D6) -> Monitoraggio attivo | C20: =IF($A20="","",'00_Scorecard'!R6) -> 0.91666667 | D20: =IF($A20="","",'00_Scorecard'!U6) -> Copertura avanzata | E20: =IF($A20="","",'00_Scorecard'!V6) -> Presidio adeguato
A21: =IF('00_Scorecard'!B7="","",'00_Scorecard'!B7) -> Fotovoltaico | B21: =IF($A21="","",'00_Scorecard'!D7) -> Monitoraggio attivo | C21: =IF($A21="","",'00_Scorecard'!R7) -> 0.91666667 | D21: =IF($A21="","",'00_Scorecard'!U7) -> Copertura avanzata | E21: =IF($A21="","",'00_Scorecard'!V7) -> Presidio adeguato
A22: =IF('00_Scorecard'!B8="","",'00_Scorecard'!B8) -> Solare Termico | B22: =IF($A22="","",'00_Scorecard'!D8) -> Monitoraggio attivo | C22: =IF($A22="","",'00_Scorecard'!R8) -> 0.91666667 | D22: =IF($A22="","",'00_Scorecard'!U8) -> Copertura avanzata | E22: =IF($A22="","",'00_Scorecard'!V8) -> Presidio adeguato
A23: =IF('00_Scorecard'!B9="","",'00_Scorecard'!B9) -> Eolico | B23: =IF($A23="","",'00_Scorecard'!D9) -> Monitoraggio attivo | C23: =IF($A23="","",'00_Scorecard'!R9) -> 0.91666667 | D23: =IF($A23="","",'00_Scorecard'!U9) -> Copertura avanzata | E23: =IF($A23="","",'00_Scorecard'!V9) -> Presidio adeguato
A24: =IF('00_Scorecard'!B10="","",'00_Scorecard'!B10) -> Idroelettrico | B24: =IF($A24="","",'00_Scorecard'!D10) -> Monitoraggio attivo | C24: =IF($A24="","",'00_Scorecard'!R10) -> 0.91666667 | D24: =IF($A24="","",'00_Scorecard'!U10) -> Copertura avanzata | E24: =IF($A24="","",'00_Scorecard'!V10) -> Presidio adeguato
A25: =IF('00_Scorecard'!B11="","",'00_Scorecard'!B11) -> Biomasse | B25: =IF($A25="","",'00_Scorecard'!D11) -> Monitoraggio attivo | C25: =IF($A25="","",'00_Scorecard'!R11) -> 0.91666667 | D25: =IF($A25="","",'00_Scorecard'!U11) -> Copertura avanzata | E25: =IF($A25="","",'00_Scorecard'!V11) -> Presidio adeguato
A26: =IF('00_Scorecard'!B12="","",'00_Scorecard'!B12) -> Geotermico | B26: =IF($A26="","",'00_Scorecard'!D12) -> Monitoraggio attivo | C26: =IF($A26="","",'00_Scorecard'!R12) -> 0.91666667 | D26: =IF($A26="","",'00_Scorecard'!U12) -> Copertura avanzata | E26: =IF($A26="","",'00_Scorecard'!V12) -> Presidio adeguato
A27: =IF('00_Scorecard'!B13="","",'00_Scorecard'!B13) -> Nucleare da fissione | B27: =IF($A27="","",'00_Scorecard'!D13) -> Monitoraggio attivo | C27: =IF($A27="","",'00_Scorecard'!R13) -> 0.91666667 | D27: =IF($A27="","",'00_Scorecard'!U13) -> Copertura avanzata | E27: =IF($A27="","",'00_Scorecard'!V13) -> Presidio adeguato
A28: =IF('00_Scorecard'!B14="","",'00_Scorecard'!B14) -> Idrogeno verde | B28: =IF($A28="","",'00_Scorecard'!D14) -> Prioritaria | C28: =IF($A28="","",'00_Scorecard'!R14) -> 0.91666667 | D28: =IF($A28="","",'00_Scorecard'!U14) -> Copertura avanzata | E28: =IF($A28="","",'00_Scorecard'!V14) -> Presidio adeguato
A29: =IF('00_Scorecard'!B15="","",'00_Scorecard'!B15) -> 0 | B29: =IF($A29="","",'00_Scorecard'!D15) -> 0 | C29: =IF($A29="","",'00_Scorecard'!R15) -> 0 | D29: =IF($A29="","",'00_Scorecard'!U15) -> Da avviare | E29: =IF($A29="","",'00_Scorecard'!V15) -> Da avviare
... A32: =IF('00_Scorecard'!B18="","",'00_Scorecard'!B18) | B32: =IF($A32="","",'00_Scorecard'!D18) | C32: =IF($A32="","",'00_Scorecard'!R18) | D32: =IF($A32="","",'00_Scorecard'!U18) | E32: =IF($A32="","",'00_Scorecard'!V18)

Sheet 00_Scorecard
A1: ERMES | Scorecard manageriale per tecnologia
A2: Foglio di sintesi automatico: misura la completezza del database ERMES per ciascuna tecnologia. Non valuta il merito tecnologico, ma il livello di copertura informativa dei dati raccolti.
A3: Tech_ID | B3: Tecnologia | C3: Macro-categoria | D3: Stato monitoraggio | E3: # Componenti | F3: # Descrizione | G3: # Avanzamento | H3: # TRL/TLR | I3: # Costi | J3: # Settori | K3: # Mercati | L3: # Sostenibilita | M3: # Best practice | N3: # Policy | O3: # Barriere/Opp. | P3: # Attori | Q3: # Prestazioni | R3: Copertura aree | S3: TRL medio | T3: Record totali | U3: Stato manageriale | V3: Priorita di popolamento
A4: =IF('03_Tecnologie'!A4="","",'03_Tecnologie'!A4) -> T001 | B4: =IF($A4="","",'03_Tecnologie'!D4) -> Carbone | C4: =IF($A4="","",'03_Tecnologie'!B4) -> Fossili | D4: =IF($A4="","",'03_Tecnologie'!F4) -> Monitoraggio attivo | E4: =IF($A4="","",COUNTIF('04_Componenti'!$B$4:$B$1000,$A4)) -> 6 | F4: =IF($A4="","",COUNTIF('05_Descrizione'!$B$4:$B$1000,$A4)) -> 6 | G4: =IF($A4="","",COUNTIF('06_Avanzamento'!$B$4:$B$1000,$A4)) -> 6 | H4: =IF($A4="","",COUNTIF('07_TRL_TLR'!$B$4:$B$1000,$A4)) -> 6 | I4: =IF($A4="","",COUNTIF('08_Costi_Compet'!$B$4:$B$1000,$A4)) -> 6 | J4: =IF($A4="","",COUNTIF('09_Settori_Impatto'!$B$4:$B$1000,$A4)) -> 6 | K4: =IF($A4="","",COUNTIF('16_Mercati_Riferimento'!$B$4:$B$1000,$A4)) -> 0 | L4: =IF($A4="","",COUNTIF('10_Sostenibilita'!$B$4:$B$1000,$A4)) -> 3 | M4: =IF($A4="","",COUNTIF('11_Best_Practice'!$B$4:$B$1000,$A4)) -> 4 | N4: =IF($A4="","",COUNTIF('12_Policy_Regolazione'!$B$4:$B$1000,$A4)) -> 5 | O4: =IF($A4="","",COUNTIF('13_Barriere_Opp'!$B$4:$B$1000,$A4)) -> 6 | P4: =IF($A4="","",COUNTIF('14_Attori_Imprese'!$B$4:$B$1000,$A4)) -> 7 | Q4: =IF($A4="","",COUNTIF('15_Prestazioni'!$B$4:$B$1000,$A4)) -> 8 | R4: =IF($A4="","",COUNTIF(F4:Q4,">0")/12) -> 0.91666667 | S4: =IF($A4="","",IFERROR(AVERAGEIF('07_TRL_TLR'!$B$4:$B$1000,$A4,'07_TRL_TLR'!$F$4:$F$1000),"")) -> 8.1666667 | T4: =IF($A4="","",SUM(F4:Q4)) -> 63 | U4: =IF($A4="","",IF(T4=0,"Da avviare",IF(R4<0.3,"Copertura base",IF(R4<0.7,"Copertura intermedia","Copertura avanzata")))) -> Copertura avanzata | V4: =IF($A4="","",IF(AND(D4="Prioritaria",R4<0.5),"Alta priorita",IF(AND(D4="Monitoraggio attivo",R4<0.3),"Media priorita",IF(T4=0,"Da avviare","Presidio adeguato")))) -> Presidio adeguato
A5: =IF('03_Tecnologie'!A5="","",'03_Tecnologie'!A5) -> T002 | B5: =IF($A5="","",'03_Tecnologie'!D5) -> Olio | C5: =IF($A5="","",'03_Tecnologie'!B5) -> Fossili | D5: =IF($A5="","",'03_Tecnologie'!F5) -> Archiviata | E5: =IF($A5="","",COUNTIF('04_Componenti'!$B$4:$B$1000,$A5)) -> 6 | F5: =IF($A5="","",COUNTIF('05_Descrizione'!$B$4:$B$1000,$A5)) -> 6 | G5: =IF($A5="","",COUNTIF('06_Avanzamento'!$B$4:$B$1000,$A5)) -> 6 | H5: =IF($A5="","",COUNTIF('07_TRL_TLR'!$B$4:$B$1000,$A5)) -> 6 | I5: =IF($A5="","",COUNTIF('08_Costi_Compet'!$B$4:$B$1000,$A5)) -> 6 | J5: =IF($A5="","",COUNTIF('09_Settori_Impatto'!$B$4:$B$1000,$A5)) -> 6 | K5: =IF($A5="","",COUNTIF('16_Mercati_Riferimento'!$B$4:$B$1000,$A5)) -> 0 | L5: =IF($A5="","",COUNTIF('10_Sostenibilita'!$B$4:$B$1000,$A5)) -> 3 | M5: =IF($A5="","",COUNTIF('11_Best_Practice'!$B$4:$B$1000,$A5)) -> 4 | N5: =IF($A5="","",COUNTIF('12_Policy_Regolazione'!$B$4:$B$1000,$A5)) -> 5 | O5: =IF($A5="","",COUNTIF('13_Barriere_Opp'!$B$4:$B$1000,$A5)) -> 6 | P5: =IF($A5="","",COUNTIF('14_Attori_Imprese'!$B$4:$B$1000,$A5)) -> 7 | Q5: =IF($A5="","",COUNTIF('15_Prestazioni'!$B$4:$B$1000,$A5)) -> 8 | R5: =IF($A5="","",COUNTIF(F5:Q5,">0")/12) -> 0.91666667 | S5: =IF($A5="","",IFERROR(AVERAGEIF('07_TRL_TLR'!$B$4:$B$1000,$A5,'07_TRL_TLR'!$F$4:$F$1000),"")) -> 8.8333333 | T5: =IF($A5="","",SUM(F5:Q5)) -> 63 | U5: =IF($A5="","",IF(T5=0,"Da avviare",IF(R5<0.3,"Copertura base",IF(R5<0.7,"Copertura intermedia","Copertura avanzata")))) -> Copertura avanzata | V5: =IF($A5="","",IF(AND(D5="Prioritaria",R5<0.5),"Alta priorita",IF(AND(D5="Monitoraggio attivo",R5<0.3),"Media priorita",IF(T5=0,"Da avviare","Presidio adeguato")))) -> Presidio adeguato
A6: =IF('03_Tecnologie'!A6="","",'03_Tecnologie'!A6) -> T003 | B6: =IF($A6="","",'03_Tecnologie'!D6) -> Gas Naturale | C6: =IF($A6="","",'03_Tecnologie'!B6) -> Fossili | D6: =IF($A6="","",'03_Tecnologie'!F6) -> Monitoraggio attivo | E6: =IF($A6="","",COUNTIF('04_Componenti'!$B$4:$B$1000,$A6)) -> 6 | F6: =IF($A6="","",COUNTIF('05_Descrizione'!$B$4:$B$1000,$A6)) -> 6 | G6: =IF($A6="","",COUNTIF('06_Avanzamento'!$B$4:$B$1000,$A6)) -> 6 | H6: =IF($A6="","",COUNTIF('07_TRL_TLR'!$B$4:$B$1000,$A6)) -> 6 | I6: =IF($A6="","",COUNTIF('08_Costi_Compet'!$B$4:$B$1000,$A6)) -> 6 | J6: =IF($A6="","",COUNTIF('09_Settori_Impatto'!$B$4:$B$1000,$A6)) -> 6 | K6: =IF($A6="","",COUNTIF('16_Mercati_Riferimento'!$B$4:$B$1000,$A6)) -> 0 | L6: =IF($A6="","",COUNTIF('10_Sostenibilita'!$B$4:$B$1000,$A6)) -> 3 | M6: =IF($A6="","",COUNTIF('11_Best_Practice'!$B$4:$B$1000,$A6)) -> 4 | N6: =IF($A6="","",COUNTIF('12_Policy_Regolazione'!$B$4:$B$1000,$A6)) -> 5 | O6: =IF($A6="","",COUNTIF('13_Barriere_Opp'!$B$4:$B$1000,$A6)) -> 6 | P6: =IF($A6="","",COUNTIF('14_Attori_Imprese'!$B$4:$B$1000,$A6)) -> 7 | Q6: =IF($A6="","",COUNTIF('15_Prestazioni'!$B$4:$B$1000,$A6)) -> 8 | R6: =IF($A6="","",COUNTIF(F6:Q6,">0")/12) -> 0.91666667 | S6: =IF($A6="","",IFERROR(AVERAGEIF('07_TRL_TLR'!$B$4:$B$1000,$A6,'07_TRL_TLR'!$F$4:$F$1000),"")) -> 8.5 | T6: =IF($A6="","",SUM(F6:Q6)) -> 63 | U6: =IF($A6="","",IF(T6=0,"Da avviare",IF(R6<0.3,"Copertura base",IF(R6<0.7,"Copertura intermedia","Copertura avanzata")))) -> Copertura avanzata | V6: =IF($A6="","",IF(AND(D6="Prioritaria",R6<0.5),"Alta priorita",IF(AND(D6="Monitoraggio attivo",R6<0.3),"Media priorita",IF(T6=0,"Da avviare","Presidio adeguato")))) -> Presidio adeguato
A7: =IF('03_Tecnologie'!A7="","",'03_Tecnologie'!A7) -> T004 | B7: =IF($A7="","",'03_Tecnologie'!D7) -> Fotovoltaico | C7: =IF($A7="","",'03_Tecnologie'!B7) -> Rinnovabili | D7: =IF($A7="","",'03_Tecnologie'!F7) -> Monitoraggio attivo | E7: =IF($A7="","",COUNTIF('04_Componenti'!$B$4:$B$1000,$A7)) -> 7 | F7: =IF($A7="","",COUNTIF('05_Descrizione'!$B$4:$B$1000,$A7)) -> 7 | G7: =IF($A7="","",COUNTIF('06_Avanzamento'!$B$4:$B$1000,$A7)) -> 6 | H7: =IF($A7="","",COUNTIF('07_TRL_TLR'!$B$4:$B$1000,$A7)) -> 6 | I7: =IF($A7="","",COUNTIF('08_Costi_Compet'!$B$4:$B$1000,$A7)) -> 6 | J7: =IF($A7="","",COUNTIF('09_Settori_Impatto'!$B$4:$B$1000,$A7)) -> 6 | K7: =IF($A7="","",COUNTIF('16_Mercati_Riferimento'!$B$4:$B$1000,$A7)) -> 0 | L7: =IF($A7="","",COUNTIF('10_Sostenibilita'!$B$4:$B$1000,$A7)) -> 3 | M7: =IF($A7="","",COUNTIF('11_Best_Practice'!$B$4:$B$1000,$A7)) -> 4 | N7: =IF($A7="","",COUNTIF('12_Policy_Regolazione'!$B$4:$B$1000,$A7)) -> 5 | O7: =IF($A7="","",COUNTIF('13_Barriere_Opp'!$B$4:$B$1000,$A7)) -> 6 | P7: =IF($A7="","",COUNTIF('14_Attori_Imprese'!$B$4:$B$1000,$A7)) -> 7 | Q7: =IF($A7="","",COUNTIF('15_Prestazioni'!$B$4:$B$1000,$A7)) -> 8 | R7: =IF($A7="","",COUNTIF(F7:Q7,">0")/12) -> 0.91666667 | S7: =IF($A7="","",IFERROR(AVERAGEIF('07_TRL_TLR'!$B$4:$B$1000,$A7,'07_TRL_TLR'!$F$4:$F$1000),"")) -> 8 | T7: =IF($A7="","",SUM(F7:Q7)) -> 64 | U7: =IF($A7="","",IF(T7=0,"Da avviare",IF(R7<0.3,"Copertura base",IF(R7<0.7,"Copertura intermedia","Copertura avanzata")))) -> Copertura avanzata | V7: =IF($A7="","",IF(AND(D7="Prioritaria",R7<0.5),"Alta priorita",IF(AND(D7="Monitoraggio attivo",R7<0.3),"Media priorita",IF(T7=0,"Da avviare","Presidio adeguato")))) -> Presidio adeguato
A8: =IF('03_Tecnologie'!A8="","",'03_Tecnologie'!A8) -> T005 | B8: =IF($A8="","",'03_Tecnologie'!D8) -> Solare Termico | C8: =IF($A8="","",'03_Tecnologie'!B8) -> Rinnovabili | D8: =IF($A8="","",'03_Tecnologie'!F8) -> Monitoraggio attivo | E8: =IF($A8="","",COUNTIF('04_Componenti'!$B$4:$B$1000,$A8)) -> 6 | F8: =IF($A8="","",COUNTIF('05_Descrizione'!$B$4:$B$1000,$A8)) -> 6 | G8: =IF($A8="","",COUNTIF('06_Avanzamento'!$B$4:$B$1000,$A8)) -> 6 | H8: =IF($A8="","",COUNTIF('07_TRL_TLR'!$B$4:$B$1000,$A8)) -> 6 | I8: =IF($A8="","",COUNTIF('08_Costi_Compet'!$B$4:$B$1000,$A8)) -> 6 | J8: =IF($A8="","",COUNTIF('09_Settori_Impatto'!$B$4:$B$1000,$A8)) -> 6 | K8: =IF($A8="","",COUNTIF('16_Mercati_Riferimento'!$B$4:$B$1000,$A8)) -> 0 | L8: =IF($A8="","",COUNTIF('10_Sostenibilita'!$B$4:$B$1000,$A8)) -> 3 | M8: =IF($A8="","",COUNTIF('11_Best_Practice'!$B$4:$B$1000,$A8)) -> 4 | N8: =IF($A8="","",COUNTIF('12_Policy_Regolazione'!$B$4:$B$1000,$A8)) -> 5 | O8: =IF($A8="","",COUNTIF('13_Barriere_Opp'!$B$4:$B$1000,$A8)) -> 6 | P8: =IF($A8="","",COUNTIF('14_Attori_Imprese'!$B$4:$B$1000,$A8)) -> 7 | Q8: =IF($A8="","",COUNTIF('15_Prestazioni'!$B$4:$B$1000,$A8)) -> 8 | R8: =IF($A8="","",COUNTIF(F8:Q8,">0")/12) -> 0.91666667 | S8: =IF($A8="","",IFERROR(AVERAGEIF('07_TRL_TLR'!$B$4:$B$1000,$A8,'07_TRL_TLR'!$F$4:$F$1000),"")) -> 8.1666667 | T8: =IF($A8="","",SUM(F8:Q8)) -> 63 | U8: =IF($A8="","",IF(T8=0,"Da avviare",IF(R8<0.3,"Copertura base",IF(R8<0.7,"Copertura intermedia","Copertura avanzata")))) -> Copertura avanzata | V8: =IF($A8="","",IF(AND(D8="Prioritaria",R8<0.5),"Alta priorita",IF(AND(D8="Monitoraggio attivo",R8<0.3),"Media priorita",IF(T8=0,"Da avviare","Presidio adeguato")))) -> Presidio adeguato
A9: =IF('03_Tecnologie'!A9="","",'03_Tecnologie'!A9) -> T006 | B9: =IF($A9="","",'03_Tecnologie'!D9) -> Eolico | C9: =IF($A9="","",'03_Tecnologie'!B9) -> Rinnovabili | D9: =IF($A9="","",'03_Tecnologie'!F9) -> Monitoraggio attivo | E9: =IF($A9="","",COUNTIF('04_Componenti'!$B$4:$B$1000,$A9)) -> 7 | F9: =IF($A9="","",COUNTIF('05_Descrizione'!$B$4:$B$1000,$A9)) -> 6 | G9: =IF($A9="","",COUNTIF('06_Avanzamento'!$B$4:$B$1000,$A9)) -> 6 | H9: =IF($A9="","",COUNTIF('07_TRL_TLR'!$B$4:$B$1000,$A9)) -> 6 | I9: =IF($A9="","",COUNTIF('08_Costi_Compet'!$B$4:$B$1000,$A9)) -> 6 | J9: =IF($A9="","",COUNTIF('09_Settori_Impatto'!$B$4:$B$1000,$A9)) -> 6 | K9: =IF($A9="","",COUNTIF('16_Mercati_Riferimento'!$B$4:$B$1000,$A9)) -> 0 | L9: =IF($A9="","",COUNTIF('10_Sostenibilita'!$B$4:$B$1000,$A9)) -> 3 | M9: =IF($A9="","",COUNTIF('11_Best_Practice'!$B$4:$B$1000,$A9)) -> 4 | N9: =IF($A9="","",COUNTIF('12_Policy_Regolazione'!$B$4:$B$1000,$A9)) -> 5 | O9: =IF($A9="","",COUNTIF('13_Barriere_Opp'!$B$4:$B$1000,$A9)) -> 6 | P9: =IF($A9="","",COUNTIF('14_Attori_Imprese'!$B$4:$B$1000,$A9)) -> 7 | Q9: =IF($A9="","",COUNTIF('15_Prestazioni'!$B$4:$B$1000,$A9)) -> 8 | R9: =IF($A9="","",COUNTIF(F9:Q9,">0")/12) -> 0.91666667 | S9: =IF($A9="","",IFERROR(AVERAGEIF('07_TRL_TLR'!$B$4:$B$1000,$A9,'07_TRL_TLR'!$F$4:$F$1000),"")) -> 8.6666667 | T9: =IF($A9="","",SUM(F9:Q9)) -> 63 | U9: =IF($A9="","",IF(T9=0,"Da avviare",IF(R9<0.3,"Copertura base",IF(R9<0.7,"Copertura intermedia","Copertura avanzata")))) -> Copertura avanzata | V9: =IF($A9="","",IF(AND(D9="Prioritaria",R9<0.5),"Alta priorita",IF(AND(D9="Monitoraggio attivo",R9<0.3),"Media priorita",IF(T9=0,"Da avviare","Presidio adeguato")))) -> Presidio adeguato
A10: =IF('03_Tecnologie'!A10="","",'03_Tecnologie'!A10) -> T007 | B10: =IF($A10="","",'03_Tecnologie'!D10) -> Idroelettrico | C10: =IF($A10="","",'03_Tecnologie'!B10) -> Rinnovabili | D10: =IF($A10="","",'03_Tecnologie'!F10) -> Monitoraggio attivo | E10: =IF($A10="","",COUNTIF('04_Componenti'!$B$4:$B$1000,$A10)) -> 6 | F10: =IF($A10="","",COUNTIF('05_Descrizione'!$B$4:$B$1000,$A10)) -> 6 | G10: =IF($A10="","",COUNTIF('06_Avanzamento'!$B$4:$B$1000,$A10)) -> 6 | H10: =IF($A10="","",COUNTIF('07_TRL_TLR'!$B$4:$B$1000,$A10)) -> 6 | I10: =IF($A10="","",COUNTIF('08_Costi_Compet'!$B$4:$B$1000,$A10)) -> 6 | J10: =IF($A10="","",COUNTIF('09_Settori_Impatto'!$B$4:$B$1000,$A10)) -> 6 | K10: =IF($A10="","",COUNTIF('16_Mercati_Riferimento'!$B$4:$B$1000,$A10)) -> 0 | L10: =IF($A10="","",COUNTIF('10_Sostenibilita'!$B$4:$B$1000,$A10)) -> 3 | M10: =IF($A10="","",COUNTIF('11_Best_Practice'!$B$4:$B$1000,$A10)) -> 4 | N10: =IF($A10="","",COUNTIF('12_Policy_Regolazione'!$B$4:$B$1000,$A10)) -> 5 | O10: =IF($A10="","",COUNTIF('13_Barriere_Opp'!$B$4:$B$1000,$A10)) -> 6 | P10: =IF($A10="","",COUNTIF('14_Attori_Imprese'!$B$4:$B$1000,$A10)) -> 7 | Q10: =IF($A10="","",COUNTIF('15_Prestazioni'!$B$4:$B$1000,$A10)) -> 8 | R10: =IF($A10="","",COUNTIF(F10:Q10,">0")/12) -> 0.91666667 | S10: =IF($A10="","",IFERROR(AVERAGEIF('07_TRL_TLR'!$B$4:$B$1000,$A10,'07_TRL_TLR'!$F$4:$F$1000),"")) -> 8.8333333 | T10: =IF($A10="","",SUM(F10:Q10)) -> 63 | U10: =IF($A10="","",IF(T10=0,"Da avviare",IF(R10<0.3,"Copertura base",IF(R10<0.7,"Copertura intermedia","Copertura avanzata")))) -> Copertura avanzata | V10: =IF($A10="","",IF(AND(D10="Prioritaria",R10<0.5),"Alta priorita",IF(AND(D10="Monitoraggio attivo",R10<0.3),"Media priorita",IF(T10=0,"Da avviare","Presidio adeguato")))) -> Presidio adeguato
A11: =IF('03_Tecnologie'!A11="","",'03_Tecnologie'!A11) -> T008 | B11: =IF($A11="","",'03_Tecnologie'!D11) -> Biomasse | C11: =IF($A11="","",'03_Tecnologie'!B11) -> Rinnovabili | D11: =IF($A11="","",'03_Tecnologie'!F11) -> Monitoraggio attivo | E11: =IF($A11="","",COUNTIF('04_Componenti'!$B$4:$B$1000,$A11)) -> 6 | F11: =IF($A11="","",COUNTIF('05_Descrizione'!$B$4:$B$1000,$A11)) -> 6 | G11: =IF($A11="","",COUNTIF('06_Avanzamento'!$B$4:$B$1000,$A11)) -> 6 | H11: =IF($A11="","",COUNTIF('07_TRL_TLR'!$B$4:$B$1000,$A11)) -> 6 | I11: =IF($A11="","",COUNTIF('08_Costi_Compet'!$B$4:$B$1000,$A11)) -> 6 | J11: =IF($A11="","",COUNTIF('09_Settori_Impatto'!$B$4:$B$1000,$A11)) -> 6 | K11: =IF($A11="","",COUNTIF('16_Mercati_Riferimento'!$B$4:$B$1000,$A11)) -> 0 | L11: =IF($A11="","",COUNTIF('10_Sostenibilita'!$B$4:$B$1000,$A11)) -> 3 | M11: =IF($A11="","",COUNTIF('11_Best_Practice'!$B$4:$B$1000,$A11)) -> 4 | N11: =IF($A11="","",COUNTIF('12_Policy_Regolazione'!$B$4:$B$1000,$A11)) -> 5 | O11: =IF($A11="","",COUNTIF('13_Barriere_Opp'!$B$4:$B$1000,$A11)) -> 6 | P11: =IF($A11="","",COUNTIF('14_Attori_Imprese'!$B$4:$B$1000,$A11)) -> 7 | Q11: =IF($A11="","",COUNTIF('15_Prestazioni'!$B$4:$B$1000,$A11)) -> 8 | R11: =IF($A11="","",COUNTIF(F11:Q11,">0")/12) -> 0.91666667 | S11: =IF($A11="","",IFERROR(AVERAGEIF('07_TRL_TLR'!$B$4:$B$1000,$A11,'07_TRL_TLR'!$F$4:$F$1000),"")) -> 8.1666667 | T11: =IF($A11="","",SUM(F11:Q11)) -> 63 | U11: =IF($A11="","",IF(T11=0,"Da avviare",IF(R11<0.3,"Copertura base",IF(R11<0.7,"Copertura intermedia","Copertura avanzata")))) -> Copertura avanzata | V11: =IF($A11="","",IF(AND(D11="Prioritaria",R11<0.5),"Alta priorita",IF(AND(D11="Monitoraggio attivo",R11<0.3),"Media priorita",IF(T11=0,"Da avviare","Presidio adeguato")))) -> Presidio adeguato
A12: =IF('03_Tecnologie'!A12="","",'03_Tecnologie'!A12) -> T009 | B12: =IF($A12="","",'03_Tecnologie'!D12) -> Geotermico | C12: =IF($A12="","",'03_Tecnologie'!B12) -> Rinnovabili | D12: =IF($A12="","",'03_Tecnologie'!F12) -> Monitoraggio attivo | E12: =IF($A12="","",COUNTIF('04_Componenti'!$B$4:$B$1000,$A12)) -> 6 | F12: =IF($A12="","",COUNTIF('05_Descrizione'!$B$4:$B$1000,$A12)) -> 6 | G12: =IF($A12="","",COUNTIF('06_Avanzamento'!$B$4:$B$1000,$A12)) -> 6 | H12: =IF($A12="","",COUNTIF('07_TRL_TLR'!$B$4:$B$1000,$A12)) -> 6 | I12: =IF($A12="","",COUNTIF('08_Costi_Compet'!$B$4:$B$1000,$A12)) -> 6 | J12: =IF($A12="","",COUNTIF('09_Settori_Impatto'!$B$4:$B$1000,$A12)) -> 6 | K12: =IF($A12="","",COUNTIF('16_Mercati_Riferimento'!$B$4:$B$1000,$A12)) -> 0 | L12: =IF($A12="","",COUNTIF('10_Sostenibilita'!$B$4:$B$1000,$A12)) -> 3 | M12: =IF($A12="","",COUNTIF('11_Best_Practice'!$B$4:$B$1000,$A12)) -> 4 | N12: =IF($A12="","",COUNTIF('12_Policy_Regolazione'!$B$4:$B$1000,$A12)) -> 5 | O12: =IF($A12="","",COUNTIF('13_Barriere_Opp'!$B$4:$B$1000,$A12)) -> 6 | P12: =IF($A12="","",COUNTIF('14_Attori_Imprese'!$B$4:$B$1000,$A12)) -> 7 | Q12: =IF($A12="","",COUNTIF('15_Prestazioni'!$B$4:$B$1000,$A12)) -> 8 | R12: =IF($A12="","",COUNTIF(F12:Q12,">0")/12) -> 0.91666667 | S12: =IF($A12="","",IFERROR(AVERAGEIF('07_TRL_TLR'!$B$4:$B$1000,$A12,'07_TRL_TLR'!$F$4:$F$1000),"")) -> 7.3333333 | T12: =IF($A12="","",SUM(F12:Q12)) -> 63 | U12: =IF($A12="","",IF(T12=0,"Da avviare",IF(R12<0.3,"Copertura base",IF(R12<0.7,"Copertura intermedia","Copertura avanzata")))) -> Copertura avanzata | V12: =IF($A12="","",IF(AND(D12="Prioritaria",R12<0.5),"Alta priorita",IF(AND(D12="Monitoraggio attivo",R12<0.3),"Media priorita",IF(T12=0,"Da avviare","Presidio adeguato")))) -> Presidio adeguato
A13: =IF('03_Tecnologie'!A13="","",'03_Tecnologie'!A13) -> T010 | B13: =IF($A13="","",'03_Tecnologie'!D13) -> Nucleare da fissione | C13: =IF($A13="","",'03_Tecnologie'!B13) -> Basse emissioni / transitorie | D13: =IF($A13="","",'03_Tecnologie'!F13) -> Monitoraggio attivo | E13: =IF($A13="","",COUNTIF('04_Componenti'!$B$4:$B$1000,$A13)) -> 6 | F13: =IF($A13="","",COUNTIF('05_Descrizione'!$B$4:$B$1000,$A13)) -> 6 | G13: =IF($A13="","",COUNTIF('06_Avanzamento'!$B$4:$B$1000,$A13)) -> 6 | H13: =IF($A13="","",COUNTIF('07_TRL_TLR'!$B$4:$B$1000,$A13)) -> 6 | I13: =IF($A13="","",COUNTIF('08_Costi_Compet'!$B$4:$B$1000,$A13)) -> 6 | J13: =IF($A13="","",COUNTIF('09_Settori_Impatto'!$B$4:$B$1000,$A13)) -> 6 | K13: =IF($A13="","",COUNTIF('16_Mercati_Riferimento'!$B$4:$B$1000,$A13)) -> 0 | L13: =IF($A13="","",COUNTIF('10_Sostenibilita'!$B$4:$B$1000,$A13)) -> 3 | M13: =IF($A13="","",COUNTIF('11_Best_Practice'!$B$4:$B$1000,$A13)) -> 4 | N13: =IF($A13="","",COUNTIF('12_Policy_Regolazione'!$B$4:$B$1000,$A13)) -> 5 | O13: =IF($A13="","",COUNTIF('13_Barriere_Opp'!$B$4:$B$1000,$A13)) -> 6 | P13: =IF($A13="","",COUNTIF('14_Attori_Imprese'!$B$4:$B$1000,$A13)) -> 7 | Q13: =IF($A13="","",COUNTIF('15_Prestazioni'!$B$4:$B$1000,$A13)) -> 8 | R13: =IF($A13="","",COUNTIF(F13:Q13,">0")/12) -> 0.91666667 | S13: =IF($A13="","",IFERROR(AVERAGEIF('07_TRL_TLR'!$B$4:$B$1000,$A13,'07_TRL_TLR'!$F$4:$F$1000),"")) -> 8 | T13: =IF($A13="","",SUM(F13:Q13)) -> 63 | U13: =IF($A13="","",IF(T13=0,"Da avviare",IF(R13<0.3,"Copertura base",IF(R13<0.7,"Copertura intermedia","Copertura avanzata")))) -> Copertura avanzata | V13: =IF($A13="","",IF(AND(D13="Prioritaria",R13<0.5),"Alta priorita",IF(AND(D13="Monitoraggio attivo",R13<0.3),"Media priorita",IF(T13=0,"Da avviare","Presidio adeguato")))) -> Presidio adeguato
A14: =IF('03_Tecnologie'!A14="","",'03_Tecnologie'!A14) -> T011 | B14: =IF($A14="","",'03_Tecnologie'!D14) -> Idrogeno verde | C14: =IF($A14="","",'03_Tecnologie'!B14) -> Vettori innovativi | D14: =IF($A14="","",'03_Tecnologie'!F14) -> Prioritaria | E14: =IF($A14="","",COUNTIF('04_Componenti'!$B$4:$B$1000,$A14)) -> 7 | F14: =IF($A14="","",COUNTIF('05_Descrizione'!$B$4:$B$1000,$A14)) -> 6 | G14: =IF($A14="","",COUNTIF('06_Avanzamento'!$B$4:$B$1000,$A14)) -> 6 | H14: =IF($A14="","",COUNTIF('07_TRL_TLR'!$B$4:$B$1000,$A14)) -> 6 | I14: =IF($A14="","",COUNTIF('08_Costi_Compet'!$B$4:$B$1000,$A14)) -> 6 | J14: =IF($A14="","",COUNTIF('09_Settori_Impatto'!$B$4:$B$1000,$A14)) -> 6 | K14: =IF($A14="","",COUNTIF('16_Mercati_Riferimento'!$B$4:$B$1000,$A14)) -> 0 | L14: =IF($A14="","",COUNTIF('10_Sostenibilita'!$B$4:$B$1000,$A14)) -> 3 | M14: =IF($A14="","",COUNTIF('11_Best_Practice'!$B$4:$B$1000,$A14)) -> 4 | N14: =IF($A14="","",COUNTIF('12_Policy_Regolazione'!$B$4:$B$1000,$A14)) -> 5 | O14: =IF($A14="","",COUNTIF('13_Barriere_Opp'!$B$4:$B$1000,$A14)) -> 6 | P14: =IF($A14="","",COUNTIF('14_Attori_Imprese'!$B$4:$B$1000,$A14)) -> 7 | Q14: =IF($A14="","",COUNTIF('15_Prestazioni'!$B$4:$B$1000,$A14)) -> 8 | R14: =IF($A14="","",COUNTIF(F14:Q14,">0")/12) -> 0.91666667 | S14: =IF($A14="","",IFERROR(AVERAGEIF('07_TRL_TLR'!$B$4:$B$1000,$A14,'07_TRL_TLR'!$F$4:$F$1000),"")) -> 7.6666667 | T14: =IF($A14="","",SUM(F14:Q14)) -> 63 | U14: =IF($A14="","",IF(T14=0,"Da avviare",IF(R14<0.3,"Copertura base",IF(R14<0.7,"Copertura intermedia","Copertura avanzata")))) -> Copertura avanzata | V14: =IF($A14="","",IF(AND(D14="Prioritaria",R14<0.5),"Alta priorita",IF(AND(D14="Monitoraggio attivo",R14<0.3),"Media priorita",IF(T14=0,"Da avviare","Presidio adeguato")))) -> Presidio adeguato
A15: =IF('03_Tecnologie'!A15="","",'03_Tecnologie'!A15) -> T012 | B15: =IF($A15="","",'03_Tecnologie'!D15) -> 0 | C15: =IF($A15="","",'03_Tecnologie'!B15) -> Rinnovabili | D15: =IF($A15="","",'03_Tecnologie'!F15) -> 0 | E15: =IF($A15="","",COUNTIF('04_Componenti'!$B$4:$B$1000,$A15)) -> 0 | F15: =IF($A15="","",COUNTIF('05_Descrizione'!$B$4:$B$1000,$A15)) -> 0 | G15: =IF($A15="","",COUNTIF('06_Avanzamento'!$B$4:$B$1000,$A15)) -> 0 | H15: =IF($A15="","",COUNTIF('07_TRL_TLR'!$B$4:$B$1000,$A15)) -> 0 | I15: =IF($A15="","",COUNTIF('08_Costi_Compet'!$B$4:$B$1000,$A15)) -> 0 | J15: =IF($A15="","",COUNTIF('09_Settori_Impatto'!$B$4:$B$1000,$A15)) -> 0 | K15: =IF($A15="","",COUNTIF('16_Mercati_Riferimento'!$B$4:$B$1000,$A15)) -> 0 | L15: =IF($A15="","",COUNTIF('10_Sostenibilita'!$B$4:$B$1000,$A15)) -> 0 | M15: =IF($A15="","",COUNTIF('11_Best_Practice'!$B$4:$B$1000,$A15)) -> 0 | N15: =IF($A15="","",COUNTIF('12_Policy_Regolazione'!$B$4:$B$1000,$A15)) -> 0 | O15: =IF($A15="","",COUNTIF('13_Barriere_Opp'!$B$4:$B$1000,$A15)) -> 0 | P15: =IF($A15="","",COUNTIF('14_Attori_Imprese'!$B$4:$B$1000,$A15)) -> 0 | Q15: =IF($A15="","",COUNTIF('15_Prestazioni'!$B$4:$B$1000,$A15)) -> 0 | R15: =IF($A15="","",COUNTIF(F15:Q15,">0")/12) -> 0 | S15: =IF($A15="","",IFERROR(AVERAGEIF('07_TRL_TLR'!$B$4:$B$1000,$A15,'07_TRL_TLR'!$F$4:$F$1000),"")) | T15: =IF($A15="","",SUM(F15:Q15)) -> 0 | U15: =IF($A15="","",IF(T15=0,"Da avviare",IF(R15<0.3,"Copertura base",IF(R15<0.7,"Copertura intermedia","Copertura avanzata")))) -> Da avviare | V15: =IF($A15="","",IF(AND(D15="Prioritaria",R15<0.5),"Alta priorita",IF(AND(D15="Monitoraggio attivo",R15<0.3),"Media priorita",IF(T15=0,"Da avviare","Presidio adeguato")))) -> Da avviare
... A250: =IF('03_Tecnologie'!A250="","",'03_Tecnologie'!A250) | B250: =IF($A250="","",'03_Tecnologie'!D250) | C250: =IF($A250="","",'03_Tecnologie'!B250) | D250: =IF($A250="","",'03_Tecnologie'!F250) | E250: =IF($A250="","",COUNTIF('04_Componenti'!$B$4:$B$1000,$A250)) | F250: =IF($A250="","",COUNTIF('05_Descrizione'!$B$4:$B$1000,$A250)) | G250: =IF($A250="","",COUNTIF('06_Avanzamento'!$B$4:$B$1000,$A250)) | H250: =IF($A250="","",COUNTIF('07_TRL_TLR'!$B$4:$B$1000,$A250)) | I250: =IF($A250="","",COUNTIF('08_Costi_Compet'!$B$4:$B$1000,$A250)) | J250: =IF($A250="","",COUNTIF('09_Settori_Impatto'!$B$4:$B$1000,$A250)) | K250: =IF($A250="","",COUNTIF('16_Mercati_Riferimento'!$B$4:$B$1000,$A250)) | L250: =IF($A250="","",COUNTIF('10_Sostenibilita'!$B$4:$B$1000,$A250)) | M250: =IF($A250="","",COUNTIF('11_Best_Practice'!$B$4:$B$1000,$A250)) | N250: =IF($A250="","",COUNTIF('12_Policy_Regolazione'!$B$4:$B$1000,$A250)) | O250: =IF($A250="","",COUNTIF('13_Barriere_Opp'!$B$4:$B$1000,$A250)) | P250: =IF($A250="","",COUNTIF('14_Attori_Imprese'!$B$4:$B$1000,$A250)) | Q250: =IF($A250="","",COUNTIF('15_Prestazioni'!$B$4:$B$1000,$A250)) | R250: =IF($A250="","",COUNTIF(F250:Q250,">0")/12) | S250: =IF($A250="","",IFERROR(AVERAGEIF('07_TRL_TLR'!$B$4:$B$1000,$A250,'07_TRL_TLR'!$F$4:$F$1000),"")) | T250: =IF($A250="","",SUM(F250:Q250)) | U250: =IF($A250="","",IF(T250=0,"Da avviare",IF(R250<0.3,"Copertura base",IF(R250<0.7,"Copertura intermedia","Copertura avanzata")))) | V250: =IF($A250="","",IF(AND(D250="Prioritaria",R250<0.5),"Alta priorita",IF(AND(D250="Monitoraggio attivo",R250<0.3),"Media priorita",IF(T250=0,"Da avviare","Presidio adeguato"))))

Sheet 00_Portafoglio_Tecnologie
A1: ERMES | Portafoglio tecnologie integrato
A2: Vista sintetica per tecnologia: maturita, competitivita, sostenibilita e copertura informativa.
A4: Tech_ID | B4: Tecnologia | C4: Macro-categoria | D4: Mercato di riferimento | E4: Stato monitoraggio | F4: TRL indicativo | G4: TLR indicativo | H4: LCOE / costo indicativo | I4: GHG lifecycle | J4: Allineamento tassonomia UE | K4: Fonte primaria | L4: Scorecard row
A5: T001 | B5: Carbone | C5: Fossili | D5: Media | E5: Monitoraggio attivo | F5: 9 | G5: Medio in calo | H5: 90-160 EUR/MWh | I5: 1000 gCO2e/kWh | J5: Non allineata | K5: S077 | L5: vedi 00_Scorecard
A6: T002 | B6: Olio | C6: Fossili | D6: Media | E6: Monitoraggio attivo | F6: 9 | G6: Alto ma in calo nei segmenti power | H6: 130-220 EUR/MWh | I6: 780 gCO2e/kWh | J6: Non allineata | K6: S076 | L6: vedi 00_Scorecard
A7: T003 | B7: Gas Naturale | C7: Fossili | D7: Alta | E7: Prioritaria | F7: 9 | G7: Alto ma condizionato da policy climatiche | H7: 70-120 EUR/MWh | I7: 450 gCO2e/kWh | J7: Parzialmente allineata / transitoria | K7: S074 | L7: vedi 00_Scorecard
A8: T004 | B8: Fotovoltaico | C8: Rinnovabili | D8: Alta | E8: Prioritaria | F8: 9 | G8: Alta | H8: Molto competitivo | I8: 23 gCO2e/kWh | J8: Allineata | K8: S012 | L8: vedi 00_Scorecard
A9: T005 | B9: Solare Termico | C9: Rinnovabili | D9: Media | E9: Monitoraggio attivo | F9: 8 | G9: Medio | H9: 110-220 EUR/MWh | I9: 30 gCO2e/kWh | J9: Allineata | K9: S063 | L9: vedi 00_Scorecard
A10: T006 | B10: Eolico | C10: Rinnovabili | D10: Alta | E10: Prioritaria | F10: 9 | G10: Alta | H10: Competitivo | I10: ~10-15 gCO2e/kWh | J10: Allineata | K10: S033 | L10: vedi 00_Scorecard
A11: T007 | B11: Idroelettrico | C11: Rinnovabili | D11: Media | E11: Monitoraggio attivo | F11: 9 | G11: Alto | H11: 40-120 EUR/MWh | I11: 15 gCO2e/kWh | J11: Allineata con DNSH | K11: S068 | L11: vedi 00_Scorecard
A12: T008 | B12: Biomasse | C12: Rinnovabili | D12: Media | E12: Monitoraggio attivo | F12: 8 | G12: Medio-alto | H12: 90-180 EUR/MWh | I12: 70 gCO2e/kWh | J12: Condizionata | K12: S065 | L12: vedi 00_Scorecard
A13: T009 | B13: Geotermico | C13: Rinnovabili | D13: Media | E13: Monitoraggio attivo | F13: 8 | G13: Medio-alto | H13: 45-120 EUR/MWh | I13: 25 gCO2e/kWh | J13: Allineata | K13: S079 | L13: vedi 00_Scorecard
A14: T010 | B14: Nucleare da fissione | C14: Basse emissioni / transitorie | D14: Media | E14: In approfondimento | F14: 8 | G14: Medio-alto | H14: 90-180 EUR/MWh | I14: 12 gCO2e/kWh | J14: Condizionata | K14: S070 | L14: vedi 00_Scorecard
A15: T011 | B15: Idrogeno verde | C15: Vettori innovativi | D15: Alta | E15: Prioritaria | F15: 7-8 | G15: In crescita | H15: Fuel cost-driven | I15: molto dipende da power input | J15: Allineabile | K15: S048 | L15: vedi 00_Scorecard

Sheet 00_Guida
A1: ERMES | Template database informativo per l'Osservatorio Tecnologie Energetiche Emergenti
A2: Workbook strutturato per raccogliere dati su tecnologie, componenti, costi, sostenibilita, policy, attori e prestazioni. In questa versione manageriale apri prima 00_Executive, poi 00_Dashboard e 00_Scorecard.
A3: Navigazione consigliata: 00_Dashboard -> 00_Scorecard -> fogli tematici (05-15) -> 16_Log_Aggiornamenti
A4: 1. Logica del database | E4: 3. Filtro analitico ERMES
A5: • Ogni riga rappresenta una singola evidenza / osservazione. | E5: • Technology Watch
A6: • Le anagrafiche base sono: 02_Fonti, 03_Tecnologie, 04_Componenti. | E6: • Horizon Scanning
A7: • I fogli 05-15 raccolgono i dati tematici richiesti da ERMES. | E7: • P-TEA (assessment preliminare)
A8: • Usa sempre Tech_ID e, quando serve, Comp_ID per collegare i record. | E8: • Disseminazione / reporting
A11: 2. Regole di compilazione | E11: 4. Fogli del workbook
A12: • Compila i campi in blu (input manuale). I campi in nero sono formule di supporto. | E12: • 02_Fonti: repertorio delle fonti informative.
A13: • Una tecnologia va descritta in modo sintetico; i dettagli analitici vanno nei fogli tematici. | E13: • 03_Tecnologie: elenco delle tecnologie osservate.
A14: • Cita sempre una Fonte_ID presente nel foglio 02_Fonti e, se utile, aggiungi URL o note. | E14: • 04_Componenti: macrocomponenti / sottosistemi.
A15: • Formato data consigliato: YYYY-MM-DD. | E15: • 05-15: raccolta strutturata delle 11 aree informative richieste.
A16: • TRL/TLR: nel workbook è usata la scala standard 1-9. | E16: • 16_Log_Aggiornamenti: storico operativo degli aggiornamenti.
A18: 5. Convenzione minima consigliata per gli ID | E18: 6. Legenda colori
A19: Tech_ID | B19: T004 | C19: Fotovoltaico | E19: Input manuale | F19: esempio
A20: Comp_ID | B20: C-FV-001 | C20: Modulo FV | E20: Formula / supporto | F20: esempio
A21: Record_ID | B21: R-COST-0001 | C21: Prima osservazione costi | E21: Valori statici / anagrafiche | F21: esempio
E22: Istruzioni / attenzione | F22: esempio
A24: Fonti informative di base già precaricate nel foglio 02_Fonti: IEA, MIT Technology Review, Gartner, WEF, Cleantechnica, SETIS, JRC, BloombergNEF, Energy Innovation, NREL.
A25: Aggiornamento struttura: eliminata la colonna "Priorità ERMES"; aggiunto il foglio "09bis_Mercati_Riferimento" per valutare applicabilità in Paesi sviluppati, Paesi in via di sviluppo o entrambi.

Sheet 01_Liste
A1: MacroCategorie | B1: StatoMonitoraggio | C1: LivelloAnalisi | D1: FaseSviluppo | E1: MetricheCosto | F1: SettoriEconomici | G1: TipiPolicy | H1: CategorieBarriere | I1: TipiAttore | J1: KPI_Tecnici | K1: Geografie | L1: Mercato di riferimento | M1: TipiFonte | N1: Affidabilita | O1: TassonomiaUE | P1: FrequenzeAgg | Q1: AccessoFonte | R1: AzioniLog | S1: TRL | T1: Booleane | U1: Valute | V1: Trend | W1: IntensitaImpatto | X1: Orizzonti | Y1: StatiPolicy | Z1: BarrieraOOpportunita | AA1: EsitoVerifica
A2: Fossili | B2: Monitoraggio attivo | C2: Tecnologia | D2: Ricerca di base | E2: CAPEX | F2: Agricoltura | G2: Strategia | H2: Tecnologica | I2: Azienda | J2: Efficienza energetica | K2: Italia | L2: PS (Paesi Sviluppati) | M2: Report istituzionale | N2: 1 | O2: Allineata | P2: Continuativa | Q2: Pubblica | R2: Nuovo record | S2: 1 | T2: Sì | U2: EUR | V2: In calo | W2: Alta | X2: Breve termine | Y2: In vigore | Z2: Barriera | AA2: Da verificare
A3: Rinnovabili | B3: Archiviata | C3: Componente | D3: Proof of concept | E3: OPEX | F3: Industria | G3: Legge | H3: Economica | I3: OEM | J3: Scalabilità | K3: UE | L3: PVS Paesi in Via di Sviluppo) | M3: Paper scientifico | N3: 2 | O3: Parzialmente allineata | P3: Mensile | Q3: Abbonamento | R3: Aggiornamento | S3: 2 | T3: No | U3: USD | V3: Stabile | W3: Media | X3: Medio termine | Y3: In consultazione | Z3: Opportunità | AA3: Verificato
A4: Nucleare | C4: Sottosistema | D4: Prototipo laboratorio | E4: LCOE | F4: Trasporti | G4: Decreto | H4: Regolatoria | I4: Utility | J4: Disponibilità | K4: USA | M4: Database | N4: 3 | O4: Non allineata | P4: Trimestrale | Q4: Interna | R4: Validazione | S4: 3 | T4: Parziale | U4: GBP | V4: In aumento | W4: Bassa | X4: Lungo termine | Y4: In revisione | AA4: Parzialmente verificato
A5: Idrogeno | D5: Pilota / dimostratore | E5: LCOS | F5: Edilizia | G5: Regolazione | H5: Infrastrutturale | I5: Startup | J5: Durata utile | K5: Cina | M5: News / media specializzato | N5: 4 | O5: Da verificare | P5: Semestrale | Q5: Mista | R5: Correzione | S5: 4 | U5: Altro | V5: Volatile | Y5: Scaduta
A6: Altro | D6: FOAK (First of a kind) | E6: TCO | F6: Pubblica Amministrazione | G6: Incentivo | H6: Supply chain | I6: Centro di ricerca | J6: Emissioni dirette | K6: Asia-Pacifico | M6: Documento normativo | N6: 5 | P6: Annuale | R6: Archiviazione | S6: 5
D7: Commerciale iniziale | E7: Trend costo | F7: Utility | G7: Standard tecnico | H7: Sociale | I7: Università | J7: Fattore di capacità | K7: Globale | M7: Sito corporate | P7: Ad hoc | S7: 6
D8: Commerciale diffusa | E8: Incentivi | F8: Residenziale | G8: Tassonomia | H8: Competenze | I8: Ente pubblico | J8: Densità energetica | K8: Altro | M8: Intervista esperto | S8: 7
E9: Altro | F9: Altro | G9: Altro | H9: Opportunità | I9: Investitore | J9: Altro | M9: Altro | S9: 8
I10: Associazione | J10: Ramp rate | S10: 9
I11: Altro | J11: Round-trip efficiency
J12: Heat rate
J13: Capture rate CO2
J14: Ore di accumulo termico
J15: Vita utile tecnica

Sheet 02_Fonti
A1: 02_Fonti | Repertorio fonti informative
A2: Precaricate le principali fonti esplicitate nel brief. Aggiungere qui eventuali fonti FEEM / interne / di progetto prima di usarle nei fogli analitici.
A3: Source_ID | B3: Nome fonte | C3: Categoria fonte | D3: Organizzazione | E3: URL | F3: Copertura / ambito | G3: Frequenza agg. | H3: Accesso | I3: Affidabilità (1-5) | J3: Note operative
A4: S001 | B4: IEA - Tracking Clean Energy Progress | C4: Report istituzionale | D4: IEA | E4: https://www.iea.org/topics/tracking-clean-energy-progress | F4: monitoraggio progresso clean energy | G4: Continuativa | H4: Pubblica | I4: 5 | J4: Fonte istituzionale di monitoraggio
A5: S002 | B5: IEA - Technology Innovation | C5: Report istituzionale | D5: IEA | E5: https://www.iea.org/topics/technology-innovation | F5: rapporti e analisi su innovazione energetica | G5: Continuativa | H5: Pubblica | I5: 5
A6: S003 | B6: MIT Technology Review | C6: News / media specializzato | D6: MIT Technology Review | E6: https://www.technologyreview.com/ | F6: trend e segnali deboli tecnologici | G6: Continuativa | H6: Pubblica | I6: 3 | J6: utile per horizon scanning
A7: S004 | B7: Gartner - Hype Cycle | C7: Report istituzionale | D7: Gartner | E7: https://www.gartner.com/en/research/methodologies/gartner-hype-cycle | F7: maturità e hype di tecnologie | G7: Annuale | H7: Abbonamento | I7: 4
A8: S005 | B8: World Economic Forum - Strategic Intelligence | C8: Database | D8: World Economic Forum | E8: https://intelligence.weforum.org/ | F8: trend, temi strategici e correlazioni | G8: Continuativa | H8: Pubblica | I8: 3
A9: S006 | B9: Cleantechnica | C9: News / media specializzato | D9: Cleantechnica | E9: https://cleantechnica.com/ | F9: notizie e casi applicativi clean tech | G9: Continuativa | H9: Pubblica | I9: 2 | J9: da validare sempre con fonti primarie
A10: S007 | B10: SETIS - Strategic Energy Technology Information System | C10: Database | D10: Commissione Europea | E10: https://setis.ec.europa.eu/ | F10: informazioni su tecnologie SET europee | G10: Continuativa | H10: Pubblica | I10: 5
A11: S008 | B11: JRC - Technology Innovation Watch | C11: Report istituzionale | D11: Joint Research Centre | E11: https://ec.europa.eu/jrc/en/research-topic/energy-technologies-and-innovation | F11: sorveglianza innovazione tecnologica | G11: Continuativa | H11: Pubblica | I11: 5
A12: S009 | B12: BloombergNEF | C12: Database | D12: BloombergNEF | E12: https://about.bnef.com/ | F12: mercati, costi, investimenti, benchmark | G12: Continuativa | H12: Abbonamento | I12: 5
A13: S010 | B13: Energy Innovation - Technology Policy Insights | C13: Report istituzionale | D13: Energy Innovation | E13: https://energyinnovation.org/our-work/energy-policy-solutions/ | F13: policy insight e technology policy | G13: Continuativa | H13: Pubblica | I13: 4
A14: S011 | B14: NREL Research | C14: Report istituzionale | D14: NREL | E14: https://www.nrel.gov/research/ | F14: ricerca applicata e benchmark tecnologici | G14: Continuativa | H14: Pubblica | I14: 5
A15: S012 | B15: IEA - Solar PV | C15: Report istituzionale | D15: IEA | E15: https://www.iea.org/energy-system/renewables/solar-pv | F15: quadro globale PV: mercato, generazione, outlook | G15: Continuativa | H15: Pubblica | I15: 5 | J15: fonte primaria per scenario e ruolo della tecnologia
